[19:24:07] üîÑ Updated app!

2025-10-24 19:24:09.521 Uncaught app execution

Traceback (most recent call last):

  File "/home/adminuser/venv/lib/python3.13/site-packages/streamlit/runtime/scriptrunner/exec_code.py", line 128, in exec_func_with_error_handling

    result = func()

  File "/home/adminuser/venv/lib/python3.13/site-packages/streamlit/runtime/scriptrunner/script_runner.py", line 669, in code_to_exec

    exec(code, module.__dict__)  # noqa: S102

    ~~~~^^^^^^^^^^^^^^^^^^^^^^^

  File "/mount/src/advising/app.py", line 10, in <module>

    from data_upload import upload_data

  File "/mount/src/advising/data_upload.py", line 11, in <module>

    from google_drive import initialize_drive_service, sync_file_with_drive, GoogleAuthError, get_major_folder_id

  File "/mount/src/advising/google_drive.py", line 12, in <module>

    from googleapiclient.discovery import build

ModuleNotFoundError: No module named 'googleapiclient'

[19:24:09] ‚ùóÔ∏è 

2025-10-24 19:24:09.779 503 GET /script-health-check (127.0.0.1) 1877.43ms

2025-10-24 19:24:12.913 Uncaught app execution

Traceback (most recent call last):

  File "/home/adminuser/venv/lib/python3.13/site-packages/streamlit/runtime/scriptrunner/exec_code.py", line 128, in exec_func_with_error_handling

    result = func()

  File "/home/adminuser/venv/lib/python3.13/site-packages/streamlit/runtime/scriptrunner/script_runner.py", line 669, in code_to_exec

    exec(code, module.__dict__)  # noqa: S102

    ~~~~^^^^^^^^^^^^^^^^^^^^^^^

  File "/mount/src/advising/app.py", line 10, in <module>

    from data_upload import upload_data

  File "/mount/src/advising/data_upload.py", line 11, in <module>

    from google_drive import initialize_drive_service, sync_file_with_drive, GoogleAuthError, get_major_folder_id

  File "/mount/src/advising/google_drive.py", line 12, in <module>

    from googleapiclient.discovery import build

ModuleNotFoundError: No module named 'googleapiclient'

2025-10-24 19:24:13.110 503 GET /script-health-check (127.0.0.1) 207.37ms

2025-10-24 19:24:17.915 Uncaught app execution

Traceback (most recent call last):

  File "/home/adminuser/venv/lib/python3.13/site-packages/streamlit/runtime/scriptrunner/exec_code.py", line 128, in exec_func_with_error_handling

    result = func()

  File "/home/adminuser/venv/lib/python3.13/site-packages/streamlit/runtime/scriptrunner/script_runner.py", line 669, in code_to_exec

    exec(code, module.__dict__)  # noqa: S102

    ~~~~^^^^^^^^^^^^^^^^^^^^^^^

  File "/mount/src/advising/app.py", line 10, in <module>

    from data_upload import upload_data

  File "/mount/src/advising/data_upload.py", line 11, in <module>

    from google_drive import initialize_drive_service, sync_file_with_drive, GoogleAuthError, get_major_folder_id

  File "/mount/src/advising/google_drive.py", line 12, in <module>

    from googleapiclient.discovery import build

ModuleNotFoundError: No module named 'googleapiclient'

2025-10-24 19:24:18.146 503 GET /script-health-check (127.0.0.1) 237.84ms

2025-10-24 19:24:21.476 Uncaught app execution

Traceback (most recent call last):

  File "/home/adminuser/venv/lib/python3.13/site-packages/streamlit/runtime/scriptrunner/exec_code.py", line 128, in exec_func_with_error_handling

    result = func()

  File "/home/adminuser/venv/lib/python3.13/site-packages/streamlit/runtime/scriptrunner/script_runner.py", line 669, in code_to_exec

    exec(code, module.__dict__)  # noqa: S102

    ~~~~^^^^^^^^^^^^^^^^^^^^^^^

  File "/mount/src/advising/app.py", line 10, in <module>

    from data_upload import upload_data

  File "/mount/src/advising/data_upload.py", line 11, in <module>

    from google_drive import initialize_drive_service, sync_file_with_drive, GoogleAuthError, get_major_folder_id

  File "/mount/src/advising/google_drive.py", line 12, in <module>

    from googleapiclient.discovery import build

ModuleNotFoundError: No module named 'googleapiclient'

2025-10-24 19:24:22.916 Uncaught app execution

Traceback (most recent call last):

  File "/home/adminuser/venv/lib/python3.13/site-packages/streamlit/runtime/scriptrunner/exec_code.py", line 128, in exec_func_with_error_handling

    result = func()

  File "/home/adminuser/venv/lib/python3.13/site-packages/streamlit/runtime/scriptrunner/script_runner.py", line 669, in code_to_exec

    exec(code, module.__dict__)  # noqa: S102

    ~~~~^^^^^^^^^^^^^^^^^^^^^^^

  File "/mount/src/advising/app.py", line 10, in <module>

    from data_upload import upload_data

  File "/mount/src/advising/data_upload.py", line 11, in <module>

    from google_drive import initialize_drive_service, sync_file_with_drive, GoogleAuthError, get_major_folder_id

  File "/mount/src/advising/google_drive.py", line 12, in <module>

    from googleapiclient.discovery import build

ModuleNotFoundError: No module named 'googleapiclient'

2025-10-24 19:24:23.119 503 GET /script-health-check (127.0.0.1) 206.10ms

2025-10-24 19:24:27.919 Uncaught app execution

Traceback (most recent call last):

  File "/home/adminuser/venv/lib/python3.13/site-packages/streamlit/runtime/scriptrunner/exec_code.py", line 128, in exec_func_with_error_handling

    result = func()

  File "/home/adminuser/venv/lib/python3.13/site-packages/streamlit/runtime/scriptrunner/script_runner.py", line 669, in code_to_exec

    exec(code, module.__dict__)  # noqa: S102

    ~~~~^^^^^^^^^^^^^^^^^^^^^^^

  File "/mount/src/advising/app.py", line 10, in <module>

    from data_upload import upload_data

  File "/mount/src/advising/data_upload.py", line 11, in <module>

    from google_drive import initialize_drive_service, sync_file_with_drive, GoogleAuthError, get_major_folder_id

  File "/mount/src/advising/google_drive.py", line 12, in <module>

    from googleapiclient.discovery import build

ModuleNotFoundError: No module named 'googleapiclient'

2025-10-24 19:24:28.109 503 GET /script-health-check (127.0.0.1) 193.27ms

2025-10-24 19:24:32.908 Uncaught app execution

Traceback (most recent call last):

  File "/home/adminuser/venv/lib/python3.13/site-packages/streamlit/runtime/scriptrunner/exec_code.py", line 128, in exec_func_with_error_handling

    result = func()

  File "/home/adminuser/venv/lib/python3.13/site-packages/streamlit/runtime/scriptrunner/script_runner.py", line 669, in code_to_exec

    exec(code, module.__dict__)  # noqa: S102

    ~~~~^^^^^^^^^^^^^^^^^^^^^^^

  File "/mount/src/advising/app.py", line 10, in <module>

    from data_upload import upload_data

  File "/mount/src/advising/data_upload.py", line 11, in <module>

    from google_drive import initialize_drive_service, sync_file_with_drive, GoogleAuthError, get_major_folder_id

  File "/mount/src/advising/google_drive.py", line 12, in <module>

    from googleapiclient.discovery import build

ModuleNotFoundError: No module named 'googleapiclient'

2025-10-24 19:24:33.100 503 GET /script-health-check (127.0.0.1) 194.93ms

2025-10-24 19:24:37.908 Uncaught app execution

Traceback (most recent call last):

  File "/home/adminuser/venv/lib/python3.13/site-packages/streamlit/runtime/scriptrunner/exec_code.py", line 128, in exec_func_with_error_handling

    result = func()

  File "/home/adminuser/venv/lib/python3.13/site-packages/streamlit/runtime/scriptrunner/script_runner.py", line 669, in code_to_exec

    exec(code, module.__dict__)  # noqa: S102

    ~~~~^^^^^^^^^^^^^^^^^^^^^^^

  File "/mount/src/advising/app.py", line 10, in <module>

    from data_upload import upload_data

  File "/mount/src/advising/data_upload.py", line 11, in <module>

    from google_drive import initialize_drive_service, sync_file_with_drive, GoogleAuthError, get_major_folder_id

  File "/mount/src/advising/google_drive.py", line 12, in <module>

    from googleapiclient.discovery import build

ModuleNotFoundError: No module named 'googleapiclient'

2025-10-24 19:24:38.107 503 GET /script-health-check (127.0.0.1) 202.68ms

2025-10-24 19:24:42.902 Uncaught app execution

Traceback (most recent call last):

  File "/home/adminuser/venv/lib/python3.13/site-packages/streamlit/runtime/scriptrunner/exec_code.py", line 128, in exec_func_with_error_handling

    result = func()

  File "/home/adminuser/venv/lib/python3.13/site-packages/streamlit/runtime/scriptrunner/script_runner.py", line 669, in code_to_exec

    exec(code, module.__dict__)  # noqa: S102

    ~~~~^^^^^^^^^^^^^^^^^^^^^^^

  File "/mount/src/advising/app.py", line 10, in <module>

    from data_upload import upload_data

  File "/mount/src/advising/data_upload.py", line 11, in <module>

    from google_drive import initialize_drive_service, sync_file_with_drive, GoogleAuthError, get_major_folder_id

  File "/mount/src/advising/google_drive.py", line 12, in <module>

    from googleapiclient.discovery import build

ModuleNotFoundError: No module named 'googleapiclient'

2025-10-24 19:24:43.095 503 GET /script-health-check (127.0.0.1) 195.90ms

2025-10-24 19:24:47.913 Uncaught app execution

Traceback (most recent call last):

  File "/home/adminuser/venv/lib/python3.13/site-packages/streamlit/runtime/scriptrunner/exec_code.py", line 128, in exec_func_with_error_handling

    result = func()

  File "/home/adminuser/venv/lib/python3.13/site-packages/streamlit/runtime/scriptrunner/script_runner.py", line 669, in code_to_exec

    exec(code, module.__dict__)  # noqa: S102

    ~~~~^^^^^^^^^^^^^^^^^^^^^^^

  File "/mount/src/advising/app.py", line 10, in <module>

    from data_upload import upload_data

  File "/mount/src/advising/data_upload.py", line 11, in <module>

    from google_drive import initialize_drive_service, sync_file_with_drive, GoogleAuthError, get_major_folder_id

  File "/mount/src/advising/google_drive.py", line 12, in <module>

    from googleapiclient.discovery import build

ModuleNotFoundError: No module named 'googleapiclient'

2025-10-24 19:24:48.123 503 GET /script-health-check (127.0.0.1) 213.55ms